<mujoco model="picked_box">
    <worldbody>
        <body name="picked_box" pos="0 0 0" >
            <body name="door" pos="0 0.2 0.2" >
                <geom condim="3" pos="0.32 -0.14 0" friction="1 1 1" size="0.21 0.05 0.2" rgba="0.7 0.1 0.5 1" type="box" ></geom>
                <geom pos="0.52 -0.14 0.0" size="0.055 0.055 0.21" type="box" rgba="1 1 1 1"></geom>
                <geom pos="0.17 -0.07 0.049" size="0.05 0.02 0.01" type="box" rgba="0.5 0.5 0.5 1" ></geom>
                <geom pos="0.17 -0.04 0.1" size="0.05 0.01 0.06"  type="box" rgba="0.5 0.5 0.5 1" ></geom>
                <geom name="handle_box" pos="0.17 -0.03 0.155" size="0.05 0.015 0.01" type="box" rgba="1 1 1 1" friction="0.3 0.3 0.3"></geom>
                <joint armature="0.01" axis="0 0 1" damping="1" frictionloss="0.1" limited="true" name="door_hinge" pos="0.4 -0.14 0" range="-1.57 0.01" type="hinge"></joint>
                
            </body>

            <body name="frame" pos="-0.5 0.06 0.2" >
                <!-- <geom condim="3" pos="-0.1 0 0" size="0.05 0.05 0.25" rgba="1 1 0 1.0" type="box"></geom> -->
                <geom condim="3" pos="0.55 0 0" size="0.05 0.05 0.21" type="box" rgba="1 1 0 1.0"></geom>
            </body>

            <body name="latch" pos="0.14 0.13 0.3">
                <geom pos="-0.1 -0.02 0" quat="1 1 0 0" size="0.03 0.005" type="cylinder" mass="0.001" rgba="1 1 1 1"></geom>
                <geom condim="1" pos="0.02 -0.005 0" size="0.17 0.01 0.0375" type="box" rgba="1 0 0 1.0" mass="0.03"></geom>
                <geom pos="0.15 0.01 0" quat="1 1 0 0" size="0.01 0.02" type="cylinder" mass="0.001"></geom>
                <geom name="picked_box" pos="0.15 0.03 0" size="0.03 0.01 0.014" type="box" mass="0.003" rgba="1 1 1 1" friction="0.3 0.3 0.3"></geom>
                <joint armature="0.01" axis="0 1 0" damping="0.1" frictionloss="0.01" limited="true" name="latch_hinge" pos="-0.1 0.1 0" range="-2 0" type="hinge"></joint>
                                    
            </body>             
        
        </body>
        </worldbody>
</mujoco>
        




               